Workbook

Sheet Start
B1: RepLab Workout & Program Template
B2: Build a workout or a full program here, then upload this file in Trainer Central. Yellow cells are for you to fill in.
B3: QUESTIONS
B4: 1. What are you creating? | D4: =IF(C4="","⚠ Choose Single Workout or Program","✓")
B5: 2. Program name | D5: =IF($C$4<>"Program","Not needed for a single workout",IF(C5="","⚠ Required","✓"))
B6: 3. Program description (optional) | D6: =IF($C$4<>"Program","Not needed for a single workout","Optional — shown to clients")
B7: 4. Program type | D7: =IF($C$4<>"Program","Not needed for a single workout",IF(C7="","⚠ Required","✓"))
B8: 5. How many weeks? (1–52) | D8: =IF($C$4<>"Program","Not needed for a single workout",IF(C8="","⚠ Required","✓ Fill weeks 1–"&C8&" on the Schedule sheet"))
B9: 6. How many different workouts? (1–12) | D9: =IF($C$4<>"Program","Single workout: fill out the Workout 1 sheet",IF(C9="","⚠ Required","✓ Fill out Workout 1–"&C9))
B10: 7. Created by (optional) | D10: ="Your name or business — optional"
B11: SHEETS TO FILL OUT
B12: Sheet | C12: Status | D12: Problems
B13: Workout 1 | C13: =IF('Workout 1'!$O$1="FILL","FILL OUT",IF('Workout 1'!$O$1="SKIP","NOT NEEDED","Answer question 1")) | D13: =IF('Workout 1'!$O$2=0,"",'Workout 1'!$O$2&" — look for ⚠ in the Check column")
B14: Workout 2 | C14: =IF('Workout 2'!$O$1="FILL","FILL OUT",IF('Workout 2'!$O$1="SKIP","NOT NEEDED","Answer question 1")) | D14: =IF('Workout 2'!$O$2=0,"",'Workout 2'!$O$2&" — look for ⚠ in the Check column")
B15: Workout 3 | C15: =IF('Workout 3'!$O$1="FILL","FILL OUT",IF('Workout 3'!$O$1="SKIP","NOT NEEDED","Answer question 1")) | D15: =IF('Workout 3'!$O$2=0,"",'Workout 3'!$O$2&" — look for ⚠ in the Check column")
B16: Workout 4 | C16: =IF('Workout 4'!$O$1="FILL","FILL OUT",IF('Workout 4'!$O$1="SKIP","NOT NEEDED","Answer question 1")) | D16: =IF('Workout 4'!$O$2=0,"",'Workout 4'!$O$2&" — look for ⚠ in the Check column")
B17: Workout 5 | C17: =IF('Workout 5'!$O$1="FILL","FILL OUT",IF('Workout 5'!$O$1="SKIP","NOT NEEDED","Answer question 1")) | D17: =IF('Workout 5'!$O$2=0,"",'Workout 5'!$O$2&" — look for ⚠ in the Check column")
B18: Workout 6 | C18: =IF('Workout 6'!$O$1="FILL","FILL OUT",IF('Workout 6'!$O$1="SKIP","NOT NEEDED","Answer question 1")) | D18: =IF('Workout 6'!$O$2=0,"",'Workout 6'!$O$2&" — look for ⚠ in the Check column")
B19: Workout 7 | C19: =IF('Workout 7'!$O$1="FILL","FILL OUT",IF('Workout 7'!$O$1="SKIP","NOT NEEDED","Answer question 1")) | D19: =IF('Workout 7'!$O$2=0,"",'Workout 7'!$O$2&" — look for ⚠ in the Check column")
B20: Workout 8 | C20: =IF('Workout 8'!$O$1="FILL","FILL OUT",IF('Workout 8'!$O$1="SKIP","NOT NEEDED","Answer question 1")) | D20: =IF('Workout 8'!$O$2=0,"",'Workout 8'!$O$2&" — look for ⚠ in the Check column")
B21: Workout 9 | C21: =IF('Workout 9'!$O$1="FILL","FILL OUT",IF('Workout 9'!$O$1="SKIP","NOT NEEDED","Answer question 1")) | D21: =IF('Workout 9'!$O$2=0,"",'Workout 9'!$O$2&" — look for ⚠ in the Check column")
B22: Workout 10 | C22: =IF('Workout 10'!$O$1="FILL","FILL OUT",IF('Workout 10'!$O$1="SKIP","NOT NEEDED","Answer question 1")) | D22: =IF('Workout 10'!$O$2=0,"",'Workout 10'!$O$2&" — look for ⚠ in the Check column")
B23: Workout 11 | C23: =IF('Workout 11'!$O$1="FILL","FILL OUT",IF('Workout 11'!$O$1="SKIP","NOT NEEDED","Answer question 1")) | D23: =IF('Workout 11'!$O$2=0,"",'Workout 11'!$O$2&" — look for ⚠ in the Check column")
B24: Workout 12 | C24: =IF('Workout 12'!$O$1="FILL","FILL OUT",IF('Workout 12'!$O$1="SKIP","NOT NEEDED","Answer question 1")) | D24: =IF('Workout 12'!$O$2=0,"",'Workout 12'!$O$2&" — look for ⚠ in the Check column")
B25: Schedule | C25: =IF('Schedule'!$O$1="FILL","FILL OUT",IF('Schedule'!$O$1="SKIP","NOT NEEDED","Answer question 1")) | D25: =IF(Schedule!$O$2=0,"",Schedule!$O$2&" — look for ⚠ in the Check column")
B26: Exercise Library | C26: REFERENCE | D26: Look up exercises — no need to edit
B28: READY TO UPLOAD? | C28: =IF($C$4="","Answer question 1 first",IF(('Workout 1'!$O$2+'Workout 2'!$O$2+'Workout 3'!$O$2+'Workout 4'!$O$2+'Workout 5'!$O$2+'Workout 6'!$O$2+'Workout 7'!$O$2+'Workout 8'!$O$2+'Workout 9'!$O$2+'Workout 10'!$O$2+'Workout 11'!$O$2+'Workout 12'!$O$2+Schedule!$O$2+COUNTIF($D$4:$D$10,"⚠*"))=0,"✓ Ready to upload","⚠ "&('Workout 1'!$O$2+'Workout 2'!$O$2+'Workout 3'!$O$2+'Workout 4'!$O$2+'Workout 5'!$O$2+'Workout 6'!$O$2+'Workout 7'!$O$2+'Workout 8'!$O$2+'Workout 9'!$O$2+'Workout 10'!$O$2+'Workout 11'!$O$2+'Workout 12'!$O$2+Schedule!$O$2+COUNTIF($D$4:$D$10,"⚠*"))&" problem(s) to fix — see the list above"))
B30: HOW IT WORKS
B31: 1. Answer the questions above. The list of sheets turns GREEN for sheets you need to fill out and RED for sheets you can skip.
B32: 2. On each green Workout sheet: give the workout a name, then add one row per exercise.
B33: 3. Pick exercises from the Library dropdown (type to search) so clients get the demo video. Not in the library? Leave Library blank and type it in Custom Exercise with a muscle group.
B34: 4. Sets, Goal Reps and Goal Weight become the goal columns clients see in the app. Goal Weight is in lbs; leave it blank for bodyweight.
B35: 5. Different set types for one exercise (e.g. 2 warm-up sets, then 3 regular sets): use one row per set type, same exercise, one after another.
B36: 6. Supersets: give the exercises the same Superset letter (A, B, …). They are paired in the order listed (A1, A2, …).
B37: 7. Section headers ("Warm-Up", "Finisher"…): type the header in Section Header on its own row, above the exercises it covers. Coach Notes on that row become the section notes.
B38: 8. Program: on the Schedule sheet pick a workout or REST for each of the 7 days, for every week. Tip: fill Week 1, then copy it down.
B39: 9. Fix anything marked ⚠, check READY TO UPLOAD above, then upload the file in Trainer Central.
B40: Google Sheets: File → Import, or upload to Drive and open with Google Sheets. Download as .xlsx before uploading to RepLab.

Sheet Workout 1
A1: =IF($O$1="FILL","✅ FILL OUT THIS SHEET — Workout 1",IF($O$1="SKIP","⛔ NOT NEEDED — leave this sheet blank","Start on the Start sheet: answer question 1 first")) | O1: =IF(Start!$C$4="Single Workout","FILL",IF(Start!$C$4="Program",IF(1<=N(Start!$C$9),"FILL","SKIP"),""))
O2: =IF($O$1="FILL",COUNTIF($M$3:$M$56,"⚠*"),0)
B3: Workout name | G3: Workout notes | M3: =IFERROR(IF($O$1<>"FILL","",IF($C$3="","⚠ Name this workout",IF($C$3="REST","⚠ REST is reserved for rest days — pick another name",IF(COUNTIF(Lists!$A$3:$A$14,$C$3)>1,"⚠ Another workout has this name",IF(COUNTA($C$7:$D$56)=0,"⚠ Add at least one exercise","✓ Looks good"))))),"⚠ Check this row")
B4: One row per exercise (or per set type). Hover over a column title for help.
A6: # | B6: Section Header | C6: Library Exercise | D6: Custom Exercise | E6: Custom Muscle Group | F6: Superset | G6: Set Type | H6: Sets | I6: Goal Reps | J6: Rep Range | K6: Goal Weight (lbs) | L6: Coach Notes | M6: Check
A7: 1 | M7: =IFERROR(IF(AND($B7="",$C7="",$D7=""),IF(COUNTA($E7:$L7)>0,"⚠ Pick an exercise",""),IF($B7<>"",IF(COUNTA($C7:$K7)>0,"⚠ Put the section header on its own row","§ Section header"),IF(AND($C7<>"",$D7<>""),"⚠ Use Library OR Custom, not both",IF(AND($D7<>"",$E7=""),"⚠ Pick a muscle group for the custom exercise",IF(OR($H7="",$I7=""),"⚠ Enter Sets and Goal Reps",IF(IF($F7="",1=0,COUNTIF($F$7:$F$56,$F7)<2),"⚠ Superset "&$F7&" needs 2+ exercises",IF($C7<>"",IFERROR("✓ "&INDEX('Exercise Library'!$C$2:$C$319,MATCH($C7,'Exercise Library'!$B$2:$B$319,0))&IF(INDEX('Exercise Library'!$D$2:$D$319,MATCH($C7,'Exercise Library'!$B$2:$B$319,0))="Yes"," · demo video",""),"⚠ Not in the library — use Custom Exercise"),"✓ Custom ("&$E7&")"))))))),"⚠ Check this row")
A8: 2 | M8: =IFERROR(IF(AND($B8="",$C8="",$D8=""),IF(COUNTA($E8:$L8)>0,"⚠ Pick an exercise",""),IF($B8<>"",IF(COUNTA($C8:$K8)>0,"⚠ Put the section header on its own row","§ Section header"),IF(AND($C8<>"",$D8<>""),"⚠ Use Library OR Custom, not both",IF(AND($D8<>"",$E8=""),"⚠ Pick a muscle group for the custom exercise",IF(OR($H8="",$I8=""),"⚠ Enter Sets and Goal Reps",IF(IF($F8="",1=0,COUNTIF($F$7:$F$56,$F8)<2),"⚠ Superset "&$F8&" needs 2+ exercises",IF($C8<>"",IFERROR("✓ "&INDEX('Exercise Library'!$C$2:$C$319,MATCH($C8,'Exercise Library'!$B$2:$B$319,0))&IF(INDEX('Exercise Library'!$D$2:$D$319,MATCH($C8,'Exercise Library'!$B$2:$B$319,0))="Yes"," · demo video",""),"⚠ Not in the library — use Custom Exercise"),"✓ Custom ("&$E8&")"))))))),"⚠ Check this row")
A9: 3 | M9: =IFERROR(IF(AND($B9="",$C9="",$D9=""),IF(COUNTA($E9:$L9)>0,"⚠ Pick an exercise",""),IF($B9<>"",IF(COUNTA($C9:$K9)>0,"⚠ Put the section header on its own row","§ Section header"),IF(AND($C9<>"",$D9<>""),"⚠ Use Library OR Custom, not both",IF(AND($D9<>"",$E9=""),"⚠ Pick a muscle group for the custom exercise",IF(OR($H9="",$I9=""),"⚠ Enter Sets and Goal Reps",IF(IF($F9="",1=0,COUNTIF($F$7:$F$56,$F9)<2),"⚠ Superset "&$F9&" needs 2+ exercises",IF($C9<>"",IFERROR("✓ "&INDEX('Exercise Library'!$C$2:$C$319,MATCH($C9,'Exercise Library'!$B$2:$B$319,0))&IF(INDEX('Exercise Library'!$D$2:$D$319,MATCH($C9,'Exercise Library'!$B$2:$B$319,0))="Yes"," · demo video",""),"⚠ Not in the library — use Custom Exercise"),"✓ Custom ("&$E9&")"))))))),"⚠ Check this row")
A10: 4 | M10: =IFERROR(IF(AND($B10="",$C10="",$D10=""),IF(COUNTA($E10:$L10)>0,"⚠ Pick an exercise",""),IF($B10<>"",IF(COUNTA($C10:$K10)>0,"⚠ Put the section header on its own row","§ Section header"),IF(AND($C10<>"",$D10<>""),"⚠ Use Library OR Custom, not both",IF(AND($D10<>"",$E10=""),"⚠ Pick a muscle group for the custom exercise",IF(OR($H10="",$I10=""),"⚠ Enter Sets and Goal Reps",IF(IF($F10="",1=0,COUNTIF($F$7:$F$56,$F10)<2),"⚠ Superset "&$F10&" needs 2+ exercises",IF($C10<>"",IFERROR("✓ "&INDEX('Exercise Library'!$C$2:$C$319,MATCH($C10,'Exercise Library'!$B$2:$B$319,0))&IF(INDEX('Exercise Library'!$D$2:$D$319,MATCH($C10,'Exercise Library'!$B$2:$B$319,0))="Yes"," · demo video",""),"⚠ Not in the library — use Custom Exercise"),"✓ Custom ("&$E10&")"))))))),"⚠ Check this row")
A11: 5 | M11: =IFERROR(IF(AND($B11="",$C11="",$D11=""),IF(COUNTA($E11:$L11)>0,"⚠ Pick an exercise",""),IF($B11<>"",IF(COUNTA($C11:$K11)>0,"⚠ Put the section header on its own row","§ Section header"),IF(AND($C11<>"",$D11<>""),"⚠ Use Library OR Custom, not both",IF(AND($D11<>"",$E11=""),"⚠ Pick a muscle group for the custom exercise",IF(OR($H11="",$I11=""),"⚠ Enter Sets and Goal Reps",IF(IF($F11="",1=0,COUNTIF($F$7:$F$56,$F11)<2),"⚠ Superset "&$F11&" needs 2+ exercises",IF($C11<>"",IFERROR("✓ "&INDEX('Exercise Library'!$C$2:$C$319,MATCH($C11,'Exercise Library'!$B$2:$B$319,0))&IF(INDEX('Exercise Library'!$D$2:$D$319,MATCH($C11,'Exercise Library'!$B$2:$B$319,0))="Yes"," · demo video",""),"⚠ Not in the library — use Custom Exercise"),"✓ Custom ("&$E11&")"))))))),"⚠ Check this row")
A12: 6 | M12: =IFERROR(IF(AND($B12="",$C12="",$D12=""),IF(COUNTA($E12:$L12)>0,"⚠ Pick an exercise",""),IF($B12<>"",IF(COUNTA($C12:$K12)>0,"⚠ Put the section header on its own row","§ Section header"),IF(AND($C12<>"",$D12<>""),"⚠ Use Library OR Custom, not both",IF(AND($D12<>"",$E12=""),"⚠ Pick a muscle group for the custom exercise",IF(OR($H12="",$I12=""),"⚠ Enter Sets and Goal Reps",IF(IF($F12="",1=0,COUNTIF($F$7:$F$56,$F12)<2),"⚠ Superset "&$F12&" needs 2+ exercises",IF($C12<>"",IFERROR("✓ "&INDEX('Exercise Library'!$C$2:$C$319,MATCH($C12,'Exercise Library'!$B$2:$B$319,0))&IF(INDEX('Exercise Library'!$D$2:$D$319,MATCH($C12,'Exercise Library'!$B$2:$B$319,0))="Yes"," · demo video",""),"⚠ Not in the library — use Custom Exercise"),"✓ Custom ("&$E12&")"))))))),"⚠ Check this row")
A13: 7 | M13: =IFERROR(IF(AND($B13="",$C13="",$D13=""),IF(COUNTA($E13:$L13)>0,"⚠ Pick an exercise",""),IF($B13<>"",IF(COUNTA($C13:$K13)>0,"⚠ Put the section header on its own row","§ Section header"),IF(AND($C13<>"",$D13<>""),"⚠ Use Library OR Custom, not both",IF(AND($D13<>"",$E13=""),"⚠ Pick a muscle group for the custom exercise",IF(OR($H13="",$I13=""),"⚠ Enter Sets and Goal Reps",IF(IF($F13="",1=0,COUNTIF($F$7:$F$56,$F13)<2),"⚠ Superset "&$F13&" needs 2+ exercises",IF($C13<>"",IFERROR("✓ "&INDEX('Exercise Library'!$C$2:$C$319,MATCH($C13,'Exercise Library'!$B$2:$B$319,0))&IF(INDEX('Exercise Library'!$D$2:$D$319,MATCH($C13,'Exercise Library'!$B$2:$B$319,0))="Yes"," · demo video",""),"⚠ Not in the library — use Custom Exercise"),"✓ Custom ("&$E13&")"))))))),"⚠ Check this row")
A14: 8 | M14: =IFERROR(IF(AND($B14="",$C14="",$D14=""),IF(COUNTA($E14:$L14)>0,"⚠ Pick an exercise",""),IF($B14<>"",IF(COUNTA($C14:$K14)>0,"⚠ Put the section header on its own row","§ Section header"),IF(AND($C14<>"",$D14<>""),"⚠ Use Library OR Custom, not both",IF(AND($D14<>"",$E14=""),"⚠ Pick a muscle group for the custom exercise",IF(OR($H14="",$I14=""),"⚠ Enter Sets and Goal Reps",IF(IF($F14="",1=0,COUNTIF($F$7:$F$56,$F14)<2),"⚠ Superset "&$F14&" needs 2+ exercises",IF($C14<>"",IFERROR("✓ "&INDEX('Exercise Library'!$C$2:$C$319,MATCH($C14,'Exercise Library'!$B$2:$B$319,0))&IF(INDEX('Exercise Library'!$D$2:$D$319,MATCH($C14,'Exercise Library'!$B$2:$B$319,0))="Yes"," · demo video",""),"⚠ Not in the library — use Custom Exercise"),"✓ Custom ("&$E14&")"))))))),"⚠ Check this row")
A15: 9 | M15: =IFERROR(IF(AND($B15="",$C15="",$D15=""),IF(COUNTA($E15:$L15)>0,"⚠ Pick an exercise",""),IF($B15<>"",IF(COUNTA($C15:$K15)>0,"⚠ Put the section header on its own row","§ Section header"),IF(AND($C15<>"",$D15<>""),"⚠ Use Library OR Custom, not both",IF(AND($D15<>"",$E15=""),"⚠ Pick a muscle group for the custom exercise",IF(OR($H15="",$I15=""),"⚠ Enter Sets and Goal Reps",IF(IF($F15="",1=0,COUNTIF($F$7:$F$56,$F15)<2),"⚠ Superset "&$F15&" needs 2+ exercises",IF($C15<>"",IFERROR("✓ "&INDEX('Exercise Library'!$C$2:$C$319,MATCH($C15,'Exercise Library'!$B$2:$B$319,0))&IF(INDEX('Exercise Library'!$D$2:$D$319,MATCH($C15,'Exercise Library'!$B$2:$B$319,0))="Yes"," · demo video",""),"⚠ Not in the library — use Custom Exercise"),"✓ Custom ("&$E15&")"))))))),"⚠ Check this row")
A16: 10 | M16: =IFERROR(IF(AND($B16="",$C16="",$D16=""),IF(COUNTA($E16:$L16)>0,"⚠ Pick an exercise",""),IF($B16<>"",IF(COUNTA($C16:$K16)>0,"⚠ Put the section header on its own row","§ Section header"),IF(AND($C16<>"",$D16<>""),"⚠ Use Library OR Custom, not both",IF(AND($D16<>"",$E16=""),"⚠ Pick a muscle group for the custom exercise",IF(OR($H16="",$I16=""),"⚠ Enter Sets and Goal Reps",IF(IF($F16="",1=0,COUNTIF($F$7:$F$56,$F16)<2),"⚠ Superset "&$F16&" needs 2+ exercises",IF($C16<>"",IFERROR("✓ "&INDEX('Exercise Library'!$C$2:$C$319,MATCH($C16,'Exercise Library'!$B$2:$B$319,0))&IF(INDEX('Exercise Library'!$D$2:$D$319,MATCH($C16,'Exercise Library'!$B$2:$B$319,0))="Yes"," · demo video",""),"⚠ Not in the library — use Custom Exercise"),"✓ Custom ("&$E16&")"))))))),"⚠ Check this row")
A17: 11 | M17: =IFERROR(IF(AND($B17="",$C17="",$D17=""),IF(COUNTA($E17:$L17)>0,"⚠ Pick an exercise",""),IF($B17<>"",IF(COUNTA($C17:$K17)>0,"⚠ Put the section header on its own row","§ Section header"),IF(AND($C17<>"",$D17<>""),"⚠ Use Library OR Custom, not both",IF(AND($D17<>"",$E17=""),"⚠ Pick a muscle group for the custom exercise",IF(OR($H17="",$I17=""),"⚠ Enter Sets and Goal Reps",IF(IF($F17="",1=0,COUNTIF($F$7:$F$56,$F17)<2),"⚠ Superset "&$F17&" needs 2+ exercises",IF($C17<>"",IFERROR("✓ "&INDEX('Exercise Library'!$C$2:$C$319,MATCH($C17,'Exercise Library'!$B$2:$B$319,0))&IF(INDEX('Exercise Library'!$D$2:$D$319,MATCH($C17,'Exercise Library'!$B$2:$B$319,0))="Yes"," · demo video",""),"⚠ Not in the library — use Custom Exercise"),"✓ Custom ("&$E17&")"))))))),"⚠ Check this row")
A18: 12 | M18: =IFERROR(IF(AND($B18="",$C18="",$D18=""),IF(COUNTA($E18:$L18)>0,"⚠ Pick an exercise",""),IF($B18<>"",IF(COUNTA($C18:$K18)>0,"⚠ Put the section header on its own row","§ Section header"),IF(AND($C18<>"",$D18<>""),"⚠ Use Library OR Custom, not both",IF(AND($D18<>"",$E18=""),"⚠ Pick a muscle group for the custom exercise",IF(OR($H18="",$I18=""),"⚠ Enter Sets and Goal Reps",IF(IF($F18="",1=0,COUNTIF($F$7:$F$56,$F18)<2),"⚠ Superset "&$F18&" needs 2+ exercises",IF($C18<>"",IFERROR("✓ "&INDEX('Exercise Library'!$C$2:$C$319,MATCH($C18,'Exercise Library'!$B$2:$B$319,0))&IF(INDEX('Exercise Library'!$D$2:$D$319,MATCH($C18,'Exercise Library'!$B$2:$B$319,0))="Yes"," · demo video",""),"⚠ Not in the library — use Custom Exercise"),"✓ Custom ("&$E18&")"))))))),"⚠ Check this row")
... A56: 50 | M56: =IFERROR(IF(AND($B56="",$C56="",$D56=""),IF(COUNTA($E56:$L56)>0,"⚠ Pick an exercise",""),IF($B56<>"",IF(COUNTA($C56:$K56)>0,"⚠ Put the section header on its own row","§ Section header"),IF(AND($C56<>"",$D56<>""),"⚠ Use Library OR Custom, not both",IF(AND($D56<>"",$E56=""),"⚠ Pick a muscle group for the custom exercise",IF(OR($H56="",$I56=""),"⚠ Enter Sets and Goal Reps",IF(IF($F56="",1=0,COUNTIF($F$7:$F$56,$F56)<2),"⚠ Superset "&$F56&" needs 2+ exercises",IF($C56<>"",IFERROR("✓ "&INDEX('Exercise Library'!$C$2:$C$319,MATCH($C56,'Exercise Library'!$B$2:$B$319,0))&IF(INDEX('Exercise Library'!$D$2:$D$319,MATCH($C56,'Exercise Library'!$B$2:$B$319,0))="Yes"," · demo video",""),"⚠ Not in the library — use Custom Exercise"),"✓ Custom ("&$E56&")"))))))),"⚠ Check this row")

Sheet Workout 2
A1: =IF($O$1="FILL","✅ FILL OUT THIS SHEET — Workout 2",IF($O$1="SKIP","⛔ NOT NEEDED — leave this sheet blank","Start on the Start sheet: answer question 1 first")) | O1: =IF(Start!$C$4="Single Workout","SKIP",IF(Start!$C$4="Program",IF(2<=N(Start!$C$9),"FILL","SKIP"),""))
O2: =IF($O$1="FILL",COUNTIF($M$3:$M$56,"⚠*"),0)
B3: Workout name | G3: Workout notes | M3: =IFERROR(IF($O$1<>"FILL","",IF($C$3="","⚠ Name this workout",IF($C$3="REST","⚠ REST is reserved for rest days — pick another name",IF(COUNTIF(Lists!$A$3:$A$14,$C$3)>1,"⚠ Another workout has this name",IF(COUNTA($C$7:$D$56)=0,"⚠ Add at least one exercise","✓ Looks good"))))),"⚠ Check this row")
B4: One row per exercise (or per set type). Hover over a column title for help.
A6: # | B6: Section Header | C6: Library Exercise | D6: Custom Exercise | E6: Custom Muscle Group | F6: Superset | G6: Set Type | H6: Sets | I6: Goal Reps | J6: Rep Range | K6: Goal Weight (lbs) | L6: Coach Notes | M6: Check
A7: 1 | M7: =IFERROR(IF(AND($B7="",$C7="",$D7=""),IF(COUNTA($E7:$L7)>0,"⚠ Pick an exercise",""),IF($B7<>"",IF(COUNTA($C7:$K7)>0,"⚠ Put the section header on its own row","§ Section header"),IF(AND($C7<>"",$D7<>""),"⚠ Use Library OR Custom, not both",IF(AND($D7<>"",$E7=""),"⚠ Pick a muscle group for the custom exercise",IF(OR($H7="",$I7=""),"⚠ Enter Sets and Goal Reps",IF(IF($F7="",1=0,COUNTIF($F$7:$F$56,$F7)<2),"⚠ Superset "&$F7&" needs 2+ exercises",IF($C7<>"",IFERROR("✓ "&INDEX('Exercise Library'!$C$2:$C$319,MATCH($C7,'Exercise Library'!$B$2:$B$319,0))&IF(INDEX('Exercise Library'!$D$2:$D$319,MATCH($C7,'Exercise Library'!$B$2:$B$319,0))="Yes"," · demo video",""),"⚠ Not in the library — use Custom Exercise"),"✓ Custom ("&$E7&")"))))))),"⚠ Check this row")
A8: 2 | M8: =IFERROR(IF(AND($B8="",$C8="",$D8=""),IF(COUNTA($E8:$L8)>0,"⚠ Pick an exercise",""),IF($B8<>"",IF(COUNTA($C8:$K8)>0,"⚠ Put the section header on its own row","§ Section header"),IF(AND($C8<>"",$D8<>""),"⚠ Use Library OR Custom, not both",IF(AND($D8<>"",$E8=""),"⚠ Pick a muscle group for the custom exercise",IF(OR($H8="",$I8=""),"⚠ Enter Sets and Goal Reps",IF(IF($F8="",1=0,COUNTIF($F$7:$F$56,$F8)<2),"⚠ Superset "&$F8&" needs 2+ exercises",IF($C8<>"",IFERROR("✓ "&INDEX('Exercise Library'!$C$2:$C$319,MATCH($C8,'Exercise Library'!$B$2:$B$319,0))&IF(INDEX('Exercise Library'!$D$2:$D$319,MATCH($C8,'Exercise Library'!$B$2:$B$319,0))="Yes"," · demo video",""),"⚠ Not in the library — use Custom Exercise"),"✓ Custom ("&$E8&")"))))))),"⚠ Check this row")
A9: 3 | M9: =IFERROR(IF(AND($B9="",$C9="",$D9=""),IF(COUNTA($E9:$L9)>0,"⚠ Pick an exercise",""),IF($B9<>"",IF(COUNTA($C9:$K9)>0,"⚠ Put the section header on its own row","§ Section header"),IF(AND($C9<>"",$D9<>""),"⚠ Use Library OR Custom, not both",IF(AND($D9<>"",$E9=""),"⚠ Pick a muscle group for the custom exercise",IF(OR($H9="",$I9=""),"⚠ Enter Sets and Goal Reps",IF(IF($F9="",1=0,COUNTIF($F$7:$F$56,$F9)<2),"⚠ Superset "&$F9&" needs 2+ exercises",IF($C9<>"",IFERROR("✓ "&INDEX('Exercise Library'!$C$2:$C$319,MATCH($C9,'Exercise Library'!$B$2:$B$319,0))&IF(INDEX('Exercise Library'!$D$2:$D$319,MATCH($C9,'Exercise Library'!$B$2:$B$319,0))="Yes"," · demo video",""),"⚠ Not in the library — use Custom Exercise"),"✓ Custom ("&$E9&")"))))))),"⚠ Check this row")
A10: 4 | M10: =IFERROR(IF(AND($B10="",$C10="",$D10=""),IF(COUNTA($E10:$L10)>0,"⚠ Pick an exercise",""),IF($B10<>"",IF(COUNTA($C10:$K10)>0,"⚠ Put the section header on its own row","§ Section header"),IF(AND($C10<>"",$D10<>""),"⚠ Use Library OR Custom, not both",IF(AND($D10<>"",$E10=""),"⚠ Pick a muscle group for the custom exercise",IF(OR($H10="",$I10=""),"⚠ Enter Sets and Goal Reps",IF(IF($F10="",1=0,COUNTIF($F$7:$F$56,$F10)<2),"⚠ Superset "&$F10&" needs 2+ exercises",IF($C10<>"",IFERROR("✓ "&INDEX('Exercise Library'!$C$2:$C$319,MATCH($C10,'Exercise Library'!$B$2:$B$319,0))&IF(INDEX('Exercise Library'!$D$2:$D$319,MATCH($C10,'Exercise Library'!$B$2:$B$319,0))="Yes"," · demo video",""),"⚠ Not in the library — use Custom Exercise"),"✓ Custom ("&$E10&")"))))))),"⚠ Check this row")
A11: 5 | M11: =IFERROR(IF(AND($B11="",$C11="",$D11=""),IF(COUNTA($E11:$L11)>0,"⚠ Pick an exercise",""),IF($B11<>"",IF(COUNTA($C11:$K11)>0,"⚠ Put the section header on its own row","§ Section header"),IF(AND($C11<>"",$D11<>""),"⚠ Use Library OR Custom, not both",IF(AND($D11<>"",$E11=""),"⚠ Pick a muscle group for the custom exercise",IF(OR($H11="",$I11=""),"⚠ Enter Sets and Goal Reps",IF(IF($F11="",1=0,COUNTIF($F$7:$F$56,$F11)<2),"⚠ Superset "&$F11&" needs 2+ exercises",IF($C11<>"",IFERROR("✓ "&INDEX('Exercise Library'!$C$2:$C$319,MATCH($C11,'Exercise Library'!$B$2:$B$319,0))&IF(INDEX('Exercise Library'!$D$2:$D$319,MATCH($C11,'Exercise Library'!$B$2:$B$319,0))="Yes"," · demo video",""),"⚠ Not in the library — use Custom Exercise"),"✓ Custom ("&$E11&")"))))))),"⚠ Check this row")
A12: 6 | M12: =IFERROR(IF(AND($B12="",$C12="",$D12=""),IF(COUNTA($E12:$L12)>0,"⚠ Pick an exercise",""),IF($B12<>"",IF(COUNTA($C12:$K12)>0,"⚠ Put the section header on its own row","§ Section header"),IF(AND($C12<>"",$D12<>""),"⚠ Use Library OR Custom, not both",IF(AND($D12<>"",$E12=""),"⚠ Pick a muscle group for the custom exercise",IF(OR($H12="",$I12=""),"⚠ Enter Sets and Goal Reps",IF(IF($F12="",1=0,COUNTIF($F$7:$F$56,$F12)<2),"⚠ Superset "&$F12&" needs 2+ exercises",IF($C12<>"",IFERROR("✓ "&INDEX('Exercise Library'!$C$2:$C$319,MATCH($C12,'Exercise Library'!$B$2:$B$319,0))&IF(INDEX('Exercise Library'!$D$2:$D$319,MATCH($C12,'Exercise Library'!$B$2:$B$319,0))="Yes"," · demo video",""),"⚠ Not in the library — use Custom Exercise"),"✓ Custom ("&$E12&")"))))))),"⚠ Check this row")
A13: 7 | M13: =IFERROR(IF(AND($B13="",$C13="",$D13=""),IF(COUNTA($E13:$L13)>0,"⚠ Pick an exercise",""),IF($B13<>"",IF(COUNTA($C13:$K13)>0,"⚠ Put the section header on its own row","§ Section header"),IF(AND($C13<>"",$D13<>""),"⚠ Use Library OR Custom, not both",IF(AND($D13<>"",$E13=""),"⚠ Pick a muscle group for the custom exercise",IF(OR($H13="",$I13=""),"⚠ Enter Sets and Goal Reps",IF(IF($F13="",1=0,COUNTIF($F$7:$F$56,$F13)<2),"⚠ Superset "&$F13&" needs 2+ exercises",IF($C13<>"",IFERROR("✓ "&INDEX('Exercise Library'!$C$2:$C$319,MATCH($C13,'Exercise Library'!$B$2:$B$319,0))&IF(INDEX('Exercise Library'!$D$2:$D$319,MATCH($C13,'Exercise Library'!$B$2:$B$319,0))="Yes"," · demo video",""),"⚠ Not in the library — use Custom Exercise"),"✓ Custom ("&$E13&")"))))))),"⚠ Check this row")
A14: 8 | M14: =IFERROR(IF(AND($B14="",$C14="",$D14=""),IF(COUNTA($E14:$L14)>0,"⚠ Pick an exercise",""),IF($B14<>"",IF(COUNTA($C14:$K14)>0,"⚠ Put the section header on its own row","§ Section header"),IF(AND($C14<>"",$D14<>""),"⚠ Use Library OR Custom, not both",IF(AND($D14<>"",$E14=""),"⚠ Pick a muscle group for the custom exercise",IF(OR($H14="",$I14=""),"⚠ Enter Sets and Goal Reps",IF(IF($F14="",1=0,COUNTIF($F$7:$F$56,$F14)<2),"⚠ Superset "&$F14&" needs 2+ exercises",IF($C14<>"",IFERROR("✓ "&INDEX('Exercise Library'!$C$2:$C$319,MATCH($C14,'Exercise Library'!$B$2:$B$319,0))&IF(INDEX('Exercise Library'!$D$2:$D$319,MATCH($C14,'Exercise Library'!$B$2:$B$319,0))="Yes"," · demo video",""),"⚠ Not in the library — use Custom Exercise"),"✓ Custom ("&$E14&")"))))))),"⚠ Check this row")
A15: 9 | M15: =IFERROR(IF(AND($B15="",$C15="",$D15=""),IF(COUNTA($E15:$L15)>0,"⚠ Pick an exercise",""),IF($B15<>"",IF(COUNTA($C15:$K15)>0,"⚠ Put the section header on its own row","§ Section header"),IF(AND($C15<>"",$D15<>""),"⚠ Use Library OR Custom, not both",IF(AND($D15<>"",$E15=""),"⚠ Pick a muscle group for the custom exercise",IF(OR($H15="",$I15=""),"⚠ Enter Sets and Goal Reps",IF(IF($F15="",1=0,COUNTIF($F$7:$F$56,$F15)<2),"⚠ Superset "&$F15&" needs 2+ exercises",IF($C15<>"",IFERROR("✓ "&INDEX('Exercise Library'!$C$2:$C$319,MATCH($C15,'Exercise Library'!$B$2:$B$319,0))&IF(INDEX('Exercise Library'!$D$2:$D$319,MATCH($C15,'Exercise Library'!$B$2:$B$319,0))="Yes"," · demo video",""),"⚠ Not in the library — use Custom Exercise"),"✓ Custom ("&$E15&")"))))))),"⚠ Check this row")
A16: 10 | M16: =IFERROR(IF(AND($B16="",$C16="",$D16=""),IF(COUNTA($E16:$L16)>0,"⚠ Pick an exercise",""),IF($B16<>"",IF(COUNTA($C16:$K16)>0,"⚠ Put the section header on its own row","§ Section header"),IF(AND($C16<>"",$D16<>""),"⚠ Use Library OR Custom, not both",IF(AND($D16<>"",$E16=""),"⚠ Pick a muscle group for the custom exercise",IF(OR($H16="",$I16=""),"⚠ Enter Sets and Goal Reps",IF(IF($F16="",1=0,COUNTIF($F$7:$F$56,$F16)<2),"⚠ Superset "&$F16&" needs 2+ exercises",IF($C16<>"",IFERROR("✓ "&INDEX('Exercise Library'!$C$2:$C$319,MATCH($C16,'Exercise Library'!$B$2:$B$319,0))&IF(INDEX('Exercise Library'!$D$2:$D$319,MATCH($C16,'Exercise Library'!$B$2:$B$319,0))="Yes"," · demo video",""),"⚠ Not in the library — use Custom Exercise"),"✓ Custom ("&$E16&")"))))))),"⚠ Check this row")
A17: 11 | M17: =IFERROR(IF(AND($B17="",$C17="",$D17=""),IF(COUNTA($E17:$L17)>0,"⚠ Pick an exercise",""),IF($B17<>"",IF(COUNTA($C17:$K17)>0,"⚠ Put the section header on its own row","§ Section header"),IF(AND($C17<>"",$D17<>""),"⚠ Use Library OR Custom, not both",IF(AND($D17<>"",$E17=""),"⚠ Pick a muscle group for the custom exercise",IF(OR($H17="",$I17=""),"⚠ Enter Sets and Goal Reps",IF(IF($F17="",1=0,COUNTIF($F$7:$F$56,$F17)<2),"⚠ Superset "&$F17&" needs 2+ exercises",IF($C17<>"",IFERROR("✓ "&INDEX('Exercise Library'!$C$2:$C$319,MATCH($C17,'Exercise Library'!$B$2:$B$319,0))&IF(INDEX('Exercise Library'!$D$2:$D$319,MATCH($C17,'Exercise Library'!$B$2:$B$319,0))="Yes"," · demo video",""),"⚠ Not in the library — use Custom Exercise"),"✓ Custom ("&$E17&")"))))))),"⚠ Check this row")
A18: 12 | M18: =IFERROR(IF(AND($B18="",$C18="",$D18=""),IF(COUNTA($E18:$L18)>0,"⚠ Pick an exercise",""),IF($B18<>"",IF(COUNTA($C18:$K18)>0,"⚠ Put the section header on its own row","§ Section header"),IF(AND($C18<>"",$D18<>""),"⚠ Use Library OR Custom, not both",IF(AND($D18<>"",$E18=""),"⚠ Pick a muscle group for the custom exercise",IF(OR($H18="",$I18=""),"⚠ Enter Sets and Goal Reps",IF(IF($F18="",1=0,COUNTIF($F$7:$F$56,$F18)<2),"⚠ Superset "&$F18&" needs 2+ exercises",IF($C18<>"",IFERROR("✓ "&INDEX('Exercise Library'!$C$2:$C$319,MATCH($C18,'Exercise Library'!$B$2:$B$319,0))&IF(INDEX('Exercise Library'!$D$2:$D$319,MATCH($C18,'Exercise Library'!$B$2:$B$319,0))="Yes"," · demo video",""),"⚠ Not in the library — use Custom Exercise"),"✓ Custom ("&$E18&")"))))))),"⚠ Check this row")
... A56: 50 | M56: =IFERROR(IF(AND($B56="",$C56="",$D56=""),IF(COUNTA($E56:$L56)>0,"⚠ Pick an exercise",""),IF($B56<>"",IF(COUNTA($C56:$K56)>0,"⚠ Put the section header on its own row","§ Section header"),IF(AND($C56<>"",$D56<>""),"⚠ Use Library OR Custom, not both",IF(AND($D56<>"",$E56=""),"⚠ Pick a muscle group for the custom exercise",IF(OR($H56="",$I56=""),"⚠ Enter Sets and Goal Reps",IF(IF($F56="",1=0,COUNTIF($F$7:$F$56,$F56)<2),"⚠ Superset "&$F56&" needs 2+ exercises",IF($C56<>"",IFERROR("✓ "&INDEX('Exercise Library'!$C$2:$C$319,MATCH($C56,'Exercise Library'!$B$2:$B$319,0))&IF(INDEX('Exercise Library'!$D$2:$D$319,MATCH($C56,'Exercise Library'!$B$2:$B$319,0))="Yes"," · demo video",""),"⚠ Not in the library — use Custom Exercise"),"✓ Custom ("&$E56&")"))))))),"⚠ Check this row")

Sheet Workout 3
A1: =IF($O$1="FILL","✅ FILL OUT THIS SHEET — Workout 3",IF($O$1="SKIP","⛔ NOT NEEDED — leave this sheet blank","Start on the Start sheet: answer question 1 first")) | O1: =IF(Start!$C$4="Single Workout","SKIP",IF(Start!$C$4="Program",IF(3<=N(Start!$C$9),"FILL","SKIP"),""))
O2: =IF($O$1="FILL",COUNTIF($M$3:$M$56,"⚠*"),0)
B3: Workout name | G3: Workout notes | M3: =IFERROR(IF($O$1<>"FILL","",IF($C$3="","⚠ Name this workout",IF($C$3="REST","⚠ REST is reserved for rest days — pick another name",IF(COUNTIF(Lists!$A$3:$A$14,$C$3)>1,"⚠ Another workout has this name",IF(COUNTA($C$7:$D$56)=0,"⚠ Add at least one exercise","✓ Looks good"))))),"⚠ Check this row")
B4: One row per exercise (or per set type). Hover over a column title for help.
A6: # | B6: Section Header | C6: Library Exercise | D6: Custom Exercise | E6: Custom Muscle Group | F6: Superset | G6: Set Type | H6: Sets | I6: Goal Reps | J6: Rep Range | K6: Goal Weight (lbs) | L6: Coach Notes | M6: Check
A7: 1 | M7: =IFERROR(IF(AND($B7="",$C7="",$D7=""),IF(COUNTA($E7:$L7)>0,"⚠ Pick an exercise",""),IF($B7<>"",IF(COUNTA($C7:$K7)>0,"⚠ Put the section header on its own row","§ Section header"),IF(AND($C7<>"",$D7<>""),"⚠ Use Library OR Custom, not both",IF(AND($D7<>"",$E7=""),"⚠ Pick a muscle group for the custom exercise",IF(OR($H7="",$I7=""),"⚠ Enter Sets and Goal Reps",IF(IF($F7="",1=0,COUNTIF($F$7:$F$56,$F7)<2),"⚠ Superset "&$F7&" needs 2+ exercises",IF($C7<>"",IFERROR("✓ "&INDEX('Exercise Library'!$C$2:$C$319,MATCH($C7,'Exercise Library'!$B$2:$B$319,0))&IF(INDEX('Exercise Library'!$D$2:$D$319,MATCH($C7,'Exercise Library'!$B$2:$B$319,0))="Yes"," · demo video",""),"⚠ Not in the library — use Custom Exercise"),"✓ Custom ("&$E7&")"))))))),"⚠ Check this row")
A8: 2 | M8: =IFERROR(IF(AND($B8="",$C8="",$D8=""),IF(COUNTA($E8:$L8)>0,"⚠ Pick an exercise",""),IF($B8<>"",IF(COUNTA($C8:$K8)>0,"⚠ Put the section header on its own row","§ Section header"),IF(AND($C8<>"",$D8<>""),"⚠ Use Library OR Custom, not both",IF(AND($D8<>"",$E8=""),"⚠ Pick a muscle group for the custom exercise",IF(OR($H8="",$I8=""),"⚠ Enter Sets and Goal Reps",IF(IF($F8="",1=0,COUNTIF($F$7:$F$56,$F8)<2),"⚠ Superset "&$F8&" needs 2+ exercises",IF($C8<>"",IFERROR("✓ "&INDEX('Exercise Library'!$C$2:$C$319,MATCH($C8,'Exercise Library'!$B$2:$B$319,0))&IF(INDEX('Exercise Library'!$D$2:$D$319,MATCH($C8,'Exercise Library'!$B$2:$B$319,0))="Yes"," · demo video",""),"⚠ Not in the library — use Custom Exercise"),"✓ Custom ("&$E8&")"))))))),"⚠ Check this row")
A9: 3 | M9: =IFERROR(IF(AND($B9="",$C9="",$D9=""),IF(COUNTA($E9:$L9)>0,"⚠ Pick an exercise",""),IF($B9<>"",IF(COUNTA($C9:$K9)>0,"⚠ Put the section header on its own row","§ Section header"),IF(AND($C9<>"",$D9<>""),"⚠ Use Library OR Custom, not both",IF(AND($D9<>"",$E9=""),"⚠ Pick a muscle group for the custom exercise",IF(OR($H9="",$I9=""),"⚠ Enter Sets and Goal Reps",IF(IF($F9="",1=0,COUNTIF($F$7:$F$56,$F9)<2),"⚠ Superset "&$F9&" needs 2+ exercises",IF($C9<>"",IFERROR("✓ "&INDEX('Exercise Library'!$C$2:$C$319,MATCH($C9,'Exercise Library'!$B$2:$B$319,0))&IF(INDEX('Exercise Library'!$D$2:$D$319,MATCH($C9,'Exercise Library'!$B$2:$B$319,0))="Yes"," · demo video",""),"⚠ Not in the library — use Custom Exercise"),"✓ Custom ("&$E9&")"))))))),"⚠ Check this row")
A10: 4 | M10: =IFERROR(IF(AND($B10="",$C10="",$D10=""),IF(COUNTA($E10:$L10)>0,"⚠ Pick an exercise",""),IF($B10<>"",IF(COUNTA($C10:$K10)>0,"⚠ Put the section header on its own row","§ Section header"),IF(AND($C10<>"",$D10<>""),"⚠ Use Library OR Custom, not both",IF(AND($D10<>"",$E10=""),"⚠ Pick a muscle group for the custom exercise",IF(OR($H10="",$I10=""),"⚠ Enter Sets and Goal Reps",IF(IF($F10="",1=0,COUNTIF($F$7:$F$56,$F10)<2),"⚠ Superset "&$F10&" needs 2+ exercises",IF($C10<>"",IFERROR("✓ "&INDEX('Exercise Library'!$C$2:$C$319,MATCH($C10,'Exercise Library'!$B$2:$B$319,0))&IF(INDEX('Exercise Library'!$D$2:$D$319,MATCH($C10,'Exercise Library'!$B$2:$B$319,0))="Yes"," · demo video",""),"⚠ Not in the library — use Custom Exercise"),"✓ Custom ("&$E10&")"))))))),"⚠ Check this row")
A11: 5 | M11: =IFERROR(IF(AND($B11="",$C11="",$D11=""),IF(COUNTA($E11:$L11)>0,"⚠ Pick an exercise",""),IF($B11<>"",IF(COUNTA($C11:$K11)>0,"⚠ Put the section header on its own row","§ Section header"),IF(AND($C11<>"",$D11<>""),"⚠ Use Library OR Custom, not both",IF(AND($D11<>"",$E11=""),"⚠ Pick a muscle group for the custom exercise",IF(OR($H11="",$I11=""),"⚠ Enter Sets and Goal Reps",IF(IF($F11="",1=0,COUNTIF($F$7:$F$56,$F11)<2),"⚠ Superset "&$F11&" needs 2+ exercises",IF($C11<>"",IFERROR("✓ "&INDEX('Exercise Library'!$C$2:$C$319,MATCH($C11,'Exercise Library'!$B$2:$B$319,0))&IF(INDEX('Exercise Library'!$D$2:$D$319,MATCH($C11,'Exercise Library'!$B$2:$B$319,0))="Yes"," · demo video",""),"⚠ Not in the library — use Custom Exercise"),"✓ Custom ("&$E11&")"))))))),"⚠ Check this row")
A12: 6 | M12: =IFERROR(IF(AND($B12="",$C12="",$D12=""),IF(COUNTA($E12:$L12)>0,"⚠ Pick an exercise",""),IF($B12<>"",IF(COUNTA($C12:$K12)>0,"⚠ Put the section header on its own row","§ Section header"),IF(AND($C12<>"",$D12<>""),"⚠ Use Library OR Custom, not both",IF(AND($D12<>"",$E12=""),"⚠ Pick a muscle group for the custom exercise",IF(OR($H12="",$I12=""),"⚠ Enter Sets and Goal Reps",IF(IF($F12="",1=0,COUNTIF($F$7:$F$56,$F12)<2),"⚠ Superset "&$F12&" needs 2+ exercises",IF($C12<>"",IFERROR("✓ "&INDEX('Exercise Library'!$C$2:$C$319,MATCH($C12,'Exercise Library'!$B$2:$B$319,0))&IF(INDEX('Exercise Library'!$D$2:$D$319,MATCH($C12,'Exercise Library'!$B$2:$B$319,0))="Yes"," · demo video",""),"⚠ Not in the library — use Custom Exercise"),"✓ Custom ("&$E12&")"))))))),"⚠ Check this row")
A13: 7 | M13: =IFERROR(IF(AND($B13="",$C13="",$D13=""),IF(COUNTA($E13:$L13)>0,"⚠ Pick an exercise",""),IF($B13<>"",IF(COUNTA($C13:$K13)>0,"⚠ Put the section header on its own row","§ Section header"),IF(AND($C13<>"",$D13<>""),"⚠ Use Library OR Custom, not both",IF(AND($D13<>"",$E13=""),"⚠ Pick a muscle group for the custom exercise",IF(OR($H13="",$I13=""),"⚠ Enter Sets and Goal Reps",IF(IF($F13="",1=0,COUNTIF($F$7:$F$56,$F13)<2),"⚠ Superset "&$F13&" needs 2+ exercises",IF($C13<>"",IFERROR("✓ "&INDEX('Exercise Library'!$C$2:$C$319,MATCH($C13,'Exercise Library'!$B$2:$B$319,0))&IF(INDEX('Exercise Library'!$D$2:$D$319,MATCH($C13,'Exercise Library'!$B$2:$B$319,0))="Yes"," · demo video",""),"⚠ Not in the library — use Custom Exercise"),"✓ Custom ("&$E13&")"))))))),"⚠ Check this row")
A14: 8 | M14: =IFERROR(IF(AND($B14="",$C14="",$D14=""),IF(COUNTA($E14:$L14)>0,"⚠ Pick an exercise",""),IF($B14<>"",IF(COUNTA($C14:$K14)>0,"⚠ Put the section header on its own row","§ Section header"),IF(AND($C14<>"",$D14<>""),"⚠ Use Library OR Custom, not both",IF(AND($D14<>"",$E14=""),"⚠ Pick a muscle group for the custom exercise",IF(OR($H14="",$I14=""),"⚠ Enter Sets and Goal Reps",IF(IF($F14="",1=0,COUNTIF($F$7:$F$56,$F14)<2),"⚠ Superset "&$F14&" needs 2+ exercises",IF($C14<>"",IFERROR("✓ "&INDEX('Exercise Library'!$C$2:$C$319,MATCH($C14,'Exercise Library'!$B$2:$B$319,0))&IF(INDEX('Exercise Library'!$D$2:$D$319,MATCH($C14,'Exercise Library'!$B$2:$B$319,0))="Yes"," · demo video",""),"⚠ Not in the library — use Custom Exercise"),"✓ Custom ("&$E14&")"))))))),"⚠ Check this row")
A15: 9 | M15: =IFERROR(IF(AND($B15="",$C15="",$D15=""),IF(COUNTA($E15:$L15)>0,"⚠ Pick an exercise",""),IF($B15<>"",IF(COUNTA($C15:$K15)>0,"⚠ Put the section header on its own row","§ Section header"),IF(AND($C15<>"",$D15<>""),"⚠ Use Library OR Custom, not both",IF(AND($D15<>"",$E15=""),"⚠ Pick a muscle group for the custom exercise",IF(OR($H15="",$I15=""),"⚠ Enter Sets and Goal Reps",IF(IF($F15="",1=0,COUNTIF($F$7:$F$56,$F15)<2),"⚠ Superset "&$F15&" needs 2+ exercises",IF($C15<>"",IFERROR("✓ "&INDEX('Exercise Library'!$C$2:$C$319,MATCH($C15,'Exercise Library'!$B$2:$B$319,0))&IF(INDEX('Exercise Library'!$D$2:$D$319,MATCH($C15,'Exercise Library'!$B$2:$B$319,0))="Yes"," · demo video",""),"⚠ Not in the library — use Custom Exercise"),"✓ Custom ("&$E15&")"))))))),"⚠ Check this row")
A16: 10 | M16: =IFERROR(IF(AND($B16="",$C16="",$D16=""),IF(COUNTA($E16:$L16)>0,"⚠ Pick an exercise",""),IF($B16<>"",IF(COUNTA($C16:$K16)>0,"⚠ Put the section header on its own row","§ Section header"),IF(AND($C16<>"",$D16<>""),"⚠ Use Library OR Custom, not both",IF(AND($D16<>"",$E16=""),"⚠ Pick a muscle group for the custom exercise",IF(OR($H16="",$I16=""),"⚠ Enter Sets and Goal Reps",IF(IF($F16="",1=0,COUNTIF($F$7:$F$56,$F16)<2),"⚠ Superset "&$F16&" needs 2+ exercises",IF($C16<>"",IFERROR("✓ "&INDEX('Exercise Library'!$C$2:$C$319,MATCH($C16,'Exercise Library'!$B$2:$B$319,0))&IF(INDEX('Exercise Library'!$D$2:$D$319,MATCH($C16,'Exercise Library'!$B$2:$B$319,0))="Yes"," · demo video",""),"⚠ Not in the library — use Custom Exercise"),"✓ Custom ("&$E16&")"))))))),"⚠ Check this row")
A17: 11 | M17: =IFERROR(IF(AND($B17="",$C17="",$D17=""),IF(COUNTA($E17:$L17)>0,"⚠ Pick an exercise",""),IF($B17<>"",IF(COUNTA($C17:$K17)>0,"⚠ Put the section header on its own row","§ Section header"),IF(AND($C17<>"",$D17<>""),"⚠ Use Library OR Custom, not both",IF(AND($D17<>"",$E17=""),"⚠ Pick a muscle group for the custom exercise",IF(OR($H17="",$I17=""),"⚠ Enter Sets and Goal Reps",IF(IF($F17="",1=0,COUNTIF($F$7:$F$56,$F17)<2),"⚠ Superset "&$F17&" needs 2+ exercises",IF($C17<>"",IFERROR("✓ "&INDEX('Exercise Library'!$C$2:$C$319,MATCH($C17,'Exercise Library'!$B$2:$B$319,0))&IF(INDEX('Exercise Library'!$D$2:$D$319,MATCH($C17,'Exercise Library'!$B$2:$B$319,0))="Yes"," · demo video",""),"⚠ Not in the library — use Custom Exercise"),"✓ Custom ("&$E17&")"))))))),"⚠ Check this row")
A18: 12 | M18: =IFERROR(IF(AND($B18="",$C18="",$D18=""),IF(COUNTA($E18:$L18)>0,"⚠ Pick an exercise",""),IF($B18<>"",IF(COUNTA($C18:$K18)>0,"⚠ Put the section header on its own row","§ Section header"),IF(AND($C18<>"",$D18<>""),"⚠ Use Library OR Custom, not both",IF(AND($D18<>"",$E18=""),"⚠ Pick a muscle group for the custom exercise",IF(OR($H18="",$I18=""),"⚠ Enter Sets and Goal Reps",IF(IF($F18="",1=0,COUNTIF($F$7:$F$56,$F18)<2),"⚠ Superset "&$F18&" needs 2+ exercises",IF($C18<>"",IFERROR("✓ "&INDEX('Exercise Library'!$C$2:$C$319,MATCH($C18,'Exercise Library'!$B$2:$B$319,0))&IF(INDEX('Exercise Library'!$D$2:$D$319,MATCH($C18,'Exercise Library'!$B$2:$B$319,0))="Yes"," · demo video",""),"⚠ Not in the library — use Custom Exercise"),"✓ Custom ("&$E18&")"))))))),"⚠ Check this row")
... A56: 50 | M56: =IFERROR(IF(AND($B56="",$C56="",$D56=""),IF(COUNTA($E56:$L56)>0,"⚠ Pick an exercise",""),IF($B56<>"",IF(COUNTA($C56:$K56)>0,"⚠ Put the section header on its own row","§ Section header"),IF(AND($C56<>"",$D56<>""),"⚠ Use Library OR Custom, not both",IF(AND($D56<>"",$E56=""),"⚠ Pick a muscle group for the custom exercise",IF(OR($H56="",$I56=""),"⚠ Enter Sets and Goal Reps",IF(IF($F56="",1=0,COUNTIF($F$7:$F$56,$F56)<2),"⚠ Superset "&$F56&" needs 2+ exercises",IF($C56<>"",IFERROR("✓ "&INDEX('Exercise Library'!$C$2:$C$319,MATCH($C56,'Exercise Library'!$B$2:$B$319,0))&IF(INDEX('Exercise Library'!$D$2:$D$319,MATCH($C56,'Exercise Library'!$B$2:$B$319,0))="Yes"," · demo video",""),"⚠ Not in the library — use Custom Exercise"),"✓ Custom ("&$E56&")"))))))),"⚠ Check this row")

Sheet Workout 4
A1: =IF($O$1="FILL","✅ FILL OUT THIS SHEET — Workout 4",IF($O$1="SKIP","⛔ NOT NEEDED — leave this sheet blank","Start on the Start sheet: answer question 1 first")) | O1: =IF(Start!$C$4="Single Workout","SKIP",IF(Start!$C$4="Program",IF(4<=N(Start!$C$9),"FILL","SKIP"),""))
O2: =IF($O$1="FILL",COUNTIF($M$3:$M$56,"⚠*"),0)
B3: Workout name | G3: Workout notes | M3: =IFERROR(IF($O$1<>"FILL","",IF($C$3="","⚠ Name this workout",IF($C$3="REST","⚠ REST is reserved for rest days — pick another name",IF(COUNTIF(Lists!$A$3:$A$14,$C$3)>1,"⚠ Another workout has this name",IF(COUNTA($C$7:$D$56)=0,"⚠ Add at least one exercise","✓ Looks good"))))),"⚠ Check this row")
B4: One row per exercise (or per set type). Hover over a column title for help.
A6: # | B6: Section Header | C6: Library Exercise | D6: Custom Exercise | E6: Custom Muscle Group | F6: Superset | G6: Set Type | H6: Sets | I6: Goal Reps | J6: Rep Range | K6: Goal Weight (lbs) | L6: Coach Notes | M6: Check
A7: 1 | M7: =IFERROR(IF(AND($B7="",$C7="",$D7=""),IF(COUNTA($E7:$L7)>0,"⚠ Pick an exercise",""),IF($B7<>"",IF(COUNTA($C7:$K7)>0,"⚠ Put the section header on its own row","§ Section header"),IF(AND($C7<>"",$D7<>""),"⚠ Use Library OR Custom, not both",IF(AND($D7<>"",$E7=""),"⚠ Pick a muscle group for the custom exercise",IF(OR($H7="",$I7=""),"⚠ Enter Sets and Goal Reps",IF(IF($F7="",1=0,COUNTIF($F$7:$F$56,$F7)<2),"⚠ Superset "&$F7&" needs 2+ exercises",IF($C7<>"",IFERROR("✓ "&INDEX('Exercise Library'!$C$2:$C$319,MATCH($C7,'Exercise Library'!$B$2:$B$319,0))&IF(INDEX('Exercise Library'!$D$2:$D$319,MATCH($C7,'Exercise Library'!$B$2:$B$319,0))="Yes"," · demo video",""),"⚠ Not in the library — use Custom Exercise"),"✓ Custom ("&$E7&")"))))))),"⚠ Check this row")
A8: 2 | M8: =IFERROR(IF(AND($B8="",$C8="",$D8=""),IF(COUNTA($E8:$L8)>0,"⚠ Pick an exercise",""),IF($B8<>"",IF(COUNTA($C8:$K8)>0,"⚠ Put the section header on its own row","§ Section header"),IF(AND($C8<>"",$D8<>""),"⚠ Use Library OR Custom, not both",IF(AND($D8<>"",$E8=""),"⚠ Pick a muscle group for the custom exercise",IF(OR($H8="",$I8=""),"⚠ Enter Sets and Goal Reps",IF(IF($F8="",1=0,COUNTIF($F$7:$F$56,$F8)<2),"⚠ Superset "&$F8&" needs 2+ exercises",IF($C8<>"",IFERROR("✓ "&INDEX('Exercise Library'!$C$2:$C$319,MATCH($C8,'Exercise Library'!$B$2:$B$319,0))&IF(INDEX('Exercise Library'!$D$2:$D$319,MATCH($C8,'Exercise Library'!$B$2:$B$319,0))="Yes"," · demo video",""),"⚠ Not in the library — use Custom Exercise"),"✓ Custom ("&$E8&")"))))))),"⚠ Check this row")
A9: 3 | M9: =IFERROR(IF(AND($B9="",$C9="",$D9=""),IF(COUNTA($E9:$L9)>0,"⚠ Pick an exercise",""),IF($B9<>"",IF(COUNTA($C9:$K9)>0,"⚠ Put the section header on its own row","§ Section header"),IF(AND($C9<>"",$D9<>""),"⚠ Use Library OR Custom, not both",IF(AND($D9<>"",$E9=""),"⚠ Pick a muscle group for the custom exercise",IF(OR($H9="",$I9=""),"⚠ Enter Sets and Goal Reps",IF(IF($F9="",1=0,COUNTIF($F$7:$F$56,$F9)<2),"⚠ Superset "&$F9&" needs 2+ exercises",IF($C9<>"",IFERROR("✓ "&INDEX('Exercise Library'!$C$2:$C$319,MATCH($C9,'Exercise Library'!$B$2:$B$319,0))&IF(INDEX('Exercise Library'!$D$2:$D$319,MATCH($C9,'Exercise Library'!$B$2:$B$319,0))="Yes"," · demo video",""),"⚠ Not in the library — use Custom Exercise"),"✓ Custom ("&$E9&")"))))))),"⚠ Check this row")
A10: 4 | M10: =IFERROR(IF(AND($B10="",$C10="",$D10=""),IF(COUNTA($E10:$L10)>0,"⚠ Pick an exercise",""),IF($B10<>"",IF(COUNTA($C10:$K10)>0,"⚠ Put the section header on its own row","§ Section header"),IF(AND($C10<>"",$D10<>""),"⚠ Use Library OR Custom, not both",IF(AND($D10<>"",$E10=""),"⚠ Pick a muscle group for the custom exercise",IF(OR($H10="",$I10=""),"⚠ Enter Sets and Goal Reps",IF(IF($F10="",1=0,COUNTIF($F$7:$F$56,$F10)<2),"⚠ Superset "&$F10&" needs 2+ exercises",IF($C10<>"",IFERROR("✓ "&INDEX('Exercise Library'!$C$2:$C$319,MATCH($C10,'Exercise Library'!$B$2:$B$319,0))&IF(INDEX('Exercise Library'!$D$2:$D$319,MATCH($C10,'Exercise Library'!$B$2:$B$319,0))="Yes"," · demo video",""),"⚠ Not in the library — use Custom Exercise"),"✓ Custom ("&$E10&")"))))))),"⚠ Check this row")
A11: 5 | M11: =IFERROR(IF(AND($B11="",$C11="",$D11=""),IF(COUNTA($E11:$L11)>0,"⚠ Pick an exercise",""),IF($B11<>"",IF(COUNTA($C11:$K11)>0,"⚠ Put the section header on its own row","§ Section header"),IF(AND($C11<>"",$D11<>""),"⚠ Use Library OR Custom, not both",IF(AND($D11<>"",$E11=""),"⚠ Pick a muscle group for the custom exercise",IF(OR($H11="",$I11=""),"⚠ Enter Sets and Goal Reps",IF(IF($F11="",1=0,COUNTIF($F$7:$F$56,$F11)<2),"⚠ Superset "&$F11&" needs 2+ exercises",IF($C11<>"",IFERROR("✓ "&INDEX('Exercise Library'!$C$2:$C$319,MATCH($C11,'Exercise Library'!$B$2:$B$319,0))&IF(INDEX('Exercise Library'!$D$2:$D$319,MATCH($C11,'Exercise Library'!$B$2:$B$319,0))="Yes"," · demo video",""),"⚠ Not in the library — use Custom Exercise"),"✓ Custom ("&$E11&")"))))))),"⚠ Check this row")
A12: 6 | M12: =IFERROR(IF(AND($B12="",$C12="",$D12=""),IF(COUNTA($E12:$L12)>0,"⚠ Pick an exercise",""),IF($B12<>"",IF(COUNTA($C12:$K12)>0,"⚠ Put the section header on its own row","§ Section header"),IF(AND($C12<>"",$D12<>""),"⚠ Use Library OR Custom, not both",IF(AND($D12<>"",$E12=""),"⚠ Pick a muscle group for the custom exercise",IF(OR($H12="",$I12=""),"⚠ Enter Sets and Goal Reps",IF(IF($F12="",1=0,COUNTIF($F$7:$F$56,$F12)<2),"⚠ Superset "&$F12&" needs 2+ exercises",IF($C12<>"",IFERROR("✓ "&INDEX('Exercise Library'!$C$2:$C$319,MATCH($C12,'Exercise Library'!$B$2:$B$319,0))&IF(INDEX('Exercise Library'!$D$2:$D$319,MATCH($C12,'Exercise Library'!$B$2:$B$319,0))="Yes"," · demo video",""),"⚠ Not in the library — use Custom Exercise"),"✓ Custom ("&$E12&")"))))))),"⚠ Check this row")
A13: 7 | M13: =IFERROR(IF(AND($B13="",$C13="",$D13=""),IF(COUNTA($E13:$L13)>0,"⚠ Pick an exercise",""),IF($B13<>"",IF(COUNTA($C13:$K13)>0,"⚠ Put the section header on its own row","§ Section header"),IF(AND($C13<>"",$D13<>""),"⚠ Use Library OR Custom, not both",IF(AND($D13<>"",$E13=""),"⚠ Pick a muscle group for the custom exercise",IF(OR($H13="",$I13=""),"⚠ Enter Sets and Goal Reps",IF(IF($F13="",1=0,COUNTIF($F$7:$F$56,$F13)<2),"⚠ Superset "&$F13&" needs 2+ exercises",IF($C13<>"",IFERROR("✓ "&INDEX('Exercise Library'!$C$2:$C$319,MATCH($C13,'Exercise Library'!$B$2:$B$319,0))&IF(INDEX('Exercise Library'!$D$2:$D$319,MATCH($C13,'Exercise Library'!$B$2:$B$319,0))="Yes"," · demo video",""),"⚠ Not in the library — use Custom Exercise"),"✓ Custom ("&$E13&")"))))))),"⚠ Check this row")
A14: 8 | M14: =IFERROR(IF(AND($B14="",$C14="",$D14=""),IF(COUNTA($E14:$L14)>0,"⚠ Pick an exercise",""),IF($B14<>"",IF(COUNTA($C14:$K14)>0,"⚠ Put the section header on its own row","§ Section header"),IF(AND($C14<>"",$D14<>""),"⚠ Use Library OR Custom, not both",IF(AND($D14<>"",$E14=""),"⚠ Pick a muscle group for the custom exercise",IF(OR($H14="",$I14=""),"⚠ Enter Sets and Goal Reps",IF(IF($F14="",1=0,COUNTIF($F$7:$F$56,$F14)<2),"⚠ Superset "&$F14&" needs 2+ exercises",IF($C14<>"",IFERROR("✓ "&INDEX('Exercise Library'!$C$2:$C$319,MATCH($C14,'Exercise Library'!$B$2:$B$319,0))&IF(INDEX('Exercise Library'!$D$2:$D$319,MATCH($C14,'Exercise Library'!$B$2:$B$319,0))="Yes"," · demo video",""),"⚠ Not in the library — use Custom Exercise"),"✓ Custom ("&$E14&")"))))))),"⚠ Check this row")
A15: 9 | M15: =IFERROR(IF(AND($B15="",$C15="",$D15=""),IF(COUNTA($E15:$L15)>0,"⚠ Pick an exercise",""),IF($B15<>"",IF(COUNTA($C15:$K15)>0,"⚠ Put the section header on its own row","§ Section header"),IF(AND($C15<>"",$D15<>""),"⚠ Use Library OR Custom, not both",IF(AND($D15<>"",$E15=""),"⚠ Pick a muscle group for the custom exercise",IF(OR($H15="",$I15=""),"⚠ Enter Sets and Goal Reps",IF(IF($F15="",1=0,COUNTIF($F$7:$F$56,$F15)<2),"⚠ Superset "&$F15&" needs 2+ exercises",IF($C15<>"",IFERROR("✓ "&INDEX('Exercise Library'!$C$2:$C$319,MATCH($C15,'Exercise Library'!$B$2:$B$319,0))&IF(INDEX('Exercise Library'!$D$2:$D$319,MATCH($C15,'Exercise Library'!$B$2:$B$319,0))="Yes"," · demo video",""),"⚠ Not in the library — use Custom Exercise"),"✓ Custom ("&$E15&")"))))))),"⚠ Check this row")
A16: 10 | M16: =IFERROR(IF(AND($B16="",$C16="",$D16=""),IF(COUNTA($E16:$L16)>0,"⚠ Pick an exercise",""),IF($B16<>"",IF(COUNTA($C16:$K16)>0,"⚠ Put the section header on its own row","§ Section header"),IF(AND($C16<>"",$D16<>""),"⚠ Use Library OR Custom, not both",IF(AND($D16<>"",$E16=""),"⚠ Pick a muscle group for the custom exercise",IF(OR($H16="",$I16=""),"⚠ Enter Sets and Goal Reps",IF(IF($F16="",1=0,COUNTIF($F$7:$F$56,$F16)<2),"⚠ Superset "&$F16&" needs 2+ exercises",IF($C16<>"",IFERROR("✓ "&INDEX('Exercise Library'!$C$2:$C$319,MATCH($C16,'Exercise Library'!$B$2:$B$319,0))&IF(INDEX('Exercise Library'!$D$2:$D$319,MATCH($C16,'Exercise Library'!$B$2:$B$319,0))="Yes"," · demo video",""),"⚠ Not in the library — use Custom Exercise"),"✓ Custom ("&$E16&")"))))))),"⚠ Check this row")
A17: 11 | M17: =IFERROR(IF(AND($B17="",$C17="",$D17=""),IF(COUNTA($E17:$L17)>0,"⚠ Pick an exercise",""),IF($B17<>"",IF(COUNTA($C17:$K17)>0,"⚠ Put the section header on its own row","§ Section header"),IF(AND($C17<>"",$D17<>""),"⚠ Use Library OR Custom, not both",IF(AND($D17<>"",$E17=""),"⚠ Pick a muscle group for the custom exercise",IF(OR($H17="",$I17=""),"⚠ Enter Sets and Goal Reps",IF(IF($F17="",1=0,COUNTIF($F$7:$F$56,$F17)<2),"⚠ Superset "&$F17&" needs 2+ exercises",IF($C17<>"",IFERROR("✓ "&INDEX('Exercise Library'!$C$2:$C$319,MATCH($C17,'Exercise Library'!$B$2:$B$319,0))&IF(INDEX('Exercise Library'!$D$2:$D$319,MATCH($C17,'Exercise Library'!$B$2:$B$319,0))="Yes"," · demo video",""),"⚠ Not in the library — use Custom Exercise"),"✓ Custom ("&$E17&")"))))))),"⚠ Check this row")
A18: 12 | M18: =IFERROR(IF(AND($B18="",$C18="",$D18=""),IF(COUNTA($E18:$L18)>0,"⚠ Pick an exercise",""),IF($B18<>"",IF(COUNTA($C18:$K18)>0,"⚠ Put the section header on its own row","§ Section header"),IF(AND($C18<>"",$D18<>""),"⚠ Use Library OR Custom, not both",IF(AND($D18<>"",$E18=""),"⚠ Pick a muscle group for the custom exercise",IF(OR($H18="",$I18=""),"⚠ Enter Sets and Goal Reps",IF(IF($F18="",1=0,COUNTIF($F$7:$F$56,$F18)<2),"⚠ Superset "&$F18&" needs 2+ exercises",IF($C18<>"",IFERROR("✓ "&INDEX('Exercise Library'!$C$2:$C$319,MATCH($C18,'Exercise Library'!$B$2:$B$319,0))&IF(INDEX('Exercise Library'!$D$2:$D$319,MATCH($C18,'Exercise Library'!$B$2:$B$319,0))="Yes"," · demo video",""),"⚠ Not in the library — use Custom Exercise"),"✓ Custom ("&$E18&")"))))))),"⚠ Check this row")
... A56: 50 | M56: =IFERROR(IF(AND($B56="",$C56="",$D56=""),IF(COUNTA($E56:$L56)>0,"⚠ Pick an exercise",""),IF($B56<>"",IF(COUNTA($C56:$K56)>0,"⚠ Put the section header on its own row","§ Section header"),IF(AND($C56<>"",$D56<>""),"⚠ Use Library OR Custom, not both",IF(AND($D56<>"",$E56=""),"⚠ Pick a muscle group for the custom exercise",IF(OR($H56="",$I56=""),"⚠ Enter Sets and Goal Reps",IF(IF($F56="",1=0,COUNTIF($F$7:$F$56,$F56)<2),"⚠ Superset "&$F56&" needs 2+ exercises",IF($C56<>"",IFERROR("✓ "&INDEX('Exercise Library'!$C$2:$C$319,MATCH($C56,'Exercise Library'!$B$2:$B$319,0))&IF(INDEX('Exercise Library'!$D$2:$D$319,MATCH($C56,'Exercise Library'!$B$2:$B$319,0))="Yes"," · demo video",""),"⚠ Not in the library — use Custom Exercise"),"✓ Custom ("&$E56&")"))))))),"⚠ Check this row")

Sheet Workout 5
A1: =IF($O$1="FILL","✅ FILL OUT THIS SHEET — Workout 5",IF($O$1="SKIP","⛔ NOT NEEDED — leave this sheet blank","Start on the Start sheet: answer question 1 first")) | O1: =IF(Start!$C$4="Single Workout","SKIP",IF(Start!$C$4="Program",IF(5<=N(Start!$C$9),"FILL","SKIP"),""))
O2: =IF($O$1="FILL",COUNTIF($M$3:$M$56,"⚠*"),0)
B3: Workout name | G3: Workout notes | M3: =IFERROR(IF($O$1<>"FILL","",IF($C$3="","⚠ Name this workout",IF($C$3="REST","⚠ REST is reserved for rest days — pick another name",IF(COUNTIF(Lists!$A$3:$A$14,$C$3)>1,"⚠ Another workout has this name",IF(COUNTA($C$7:$D$56)=0,"⚠ Add at least one exercise","✓ Looks good"))))),"⚠ Check this row")
B4: One row per exercise (or per set type). Hover over a column title for help.
A6: # | B6: Section Header | C6: Library Exercise | D6: Custom Exercise | E6: Custom Muscle Group | F6: Superset | G6: Set Type | H6: Sets | I6: Goal Reps | J6: Rep Range | K6: Goal Weight (lbs) | L6: Coach Notes | M6: Check
A7: 1 | M7: =IFERROR(IF(AND($B7="",$C7="",$D7=""),IF(COUNTA($E7:$L7)>0,"⚠ Pick an exercise",""),IF($B7<>"",IF(COUNTA($C7:$K7)>0,"⚠ Put the section header on its own row","§ Section header"),IF(AND($C7<>"",$D7<>""),"⚠ Use Library OR Custom, not both",IF(AND($D7<>"",$E7=""),"⚠ Pick a muscle group for the custom exercise",IF(OR($H7="",$I7=""),"⚠ Enter Sets and Goal Reps",IF(IF($F7="",1=0,COUNTIF($F$7:$F$56,$F7)<2),"⚠ Superset "&$F7&" needs 2+ exercises",IF($C7<>"",IFERROR("✓ "&INDEX('Exercise Library'!$C$2:$C$319,MATCH($C7,'Exercise Library'!$B$2:$B$319,0))&IF(INDEX('Exercise Library'!$D$2:$D$319,MATCH($C7,'Exercise Library'!$B$2:$B$319,0))="Yes"," · demo video",""),"⚠ Not in the library — use Custom Exercise"),"✓ Custom ("&$E7&")"))))))),"⚠ Check this row")
A8: 2 | M8: =IFERROR(IF(AND($B8="",$C8="",$D8=""),IF(COUNTA($E8:$L8)>0,"⚠ Pick an exercise",""),IF($B8<>"",IF(COUNTA($C8:$K8)>0,"⚠ Put the section header on its own row","§ Section header"),IF(AND($C8<>"",$D8<>""),"⚠ Use Library OR Custom, not both",IF(AND($D8<>"",$E8=""),"⚠ Pick a muscle group for the custom exercise",IF(OR($H8="",$I8=""),"⚠ Enter Sets and Goal Reps",IF(IF($F8="",1=0,COUNTIF($F$7:$F$56,$F8)<2),"⚠ Superset "&$F8&" needs 2+ exercises",IF($C8<>"",IFERROR("✓ "&INDEX('Exercise Library'!$C$2:$C$319,MATCH($C8,'Exercise Library'!$B$2:$B$319,0))&IF(INDEX('Exercise Library'!$D$2:$D$319,MATCH($C8,'Exercise Library'!$B$2:$B$319,0))="Yes"," · demo video",""),"⚠ Not in the library — use Custom Exercise"),"✓ Custom ("&$E8&")"))))))),"⚠ Check this row")
A9: 3 | M9: =IFERROR(IF(AND($B9="",$C9="",$D9=""),IF(COUNTA($E9:$L9)>0,"⚠ Pick an exercise",""),IF($B9<>"",IF(COUNTA($C9:$K9)>0,"⚠ Put the section header on its own row","§ Section header"),IF(AND($C9<>"",$D9<>""),"⚠ Use Library OR Custom, not both",IF(AND($D9<>"",$E9=""),"⚠ Pick a muscle group for the custom exercise",IF(OR($H9="",$I9=""),"⚠ Enter Sets and Goal Reps",IF(IF($F9="",1=0,COUNTIF($F$7:$F$56,$F9)<2),"⚠ Superset "&$F9&" needs 2+ exercises",IF($C9<>"",IFERROR("✓ "&INDEX('Exercise Library'!$C$2:$C$319,MATCH($C9,'Exercise Library'!$B$2:$B$319,0))&IF(INDEX('Exercise Library'!$D$2:$D$319,MATCH($C9,'Exercise Library'!$B$2:$B$319,0))="Yes"," · demo video",""),"⚠ Not in the library — use Custom Exercise"),"✓ Custom ("&$E9&")"))))))),"⚠ Check this row")
A10: 4 | M10: =IFERROR(IF(AND($B10="",$C10="",$D10=""),IF(COUNTA($E10:$L10)>0,"⚠ Pick an exercise",""),IF($B10<>"",IF(COUNTA($C10:$K10)>0,"⚠ Put the section header on its own row","§ Section header"),IF(AND($C10<>"",$D10<>""),"⚠ Use Library OR Custom, not both",IF(AND($D10<>"",$E10=""),"⚠ Pick a muscle group for the custom exercise",IF(OR($H10="",$I10=""),"⚠ Enter Sets and Goal Reps",IF(IF($F10="",1=0,COUNTIF($F$7:$F$56,$F10)<2),"⚠ Superset "&$F10&" needs 2+ exercises",IF($C10<>"",IFERROR("✓ "&INDEX('Exercise Library'!$C$2:$C$319,MATCH($C10,'Exercise Library'!$B$2:$B$319,0))&IF(INDEX('Exercise Library'!$D$2:$D$319,MATCH($C10,'Exercise Library'!$B$2:$B$319,0))="Yes"," · demo video",""),"⚠ Not in the library — use Custom Exercise"),"✓ Custom ("&$E10&")"))))))),"⚠ Check this row")
A11: 5 | M11: =IFERROR(IF(AND($B11="",$C11="",$D11=""),IF(COUNTA($E11:$L11)>0,"⚠ Pick an exercise",""),IF($B11<>"",IF(COUNTA($C11:$K11)>0,"⚠ Put the section header on its own row","§ Section header"),IF(AND($C11<>"",$D11<>""),"⚠ Use Library OR Custom, not both",IF(AND($D11<>"",$E11=""),"⚠ Pick a muscle group for the custom exercise",IF(OR($H11="",$I11=""),"⚠ Enter Sets and Goal Reps",IF(IF($F11="",1=0,COUNTIF($F$7:$F$56,$F11)<2),"⚠ Superset "&$F11&" needs 2+ exercises",IF($C11<>"",IFERROR("✓ "&INDEX('Exercise Library'!$C$2:$C$319,MATCH($C11,'Exercise Library'!$B$2:$B$319,0))&IF(INDEX('Exercise Library'!$D$2:$D$319,MATCH($C11,'Exercise Library'!$B$2:$B$319,0))="Yes"," · demo video",""),"⚠ Not in the library — use Custom Exercise"),"✓ Custom ("&$E11&")"))))))),"⚠ Check this row")
A12: 6 | M12: =IFERROR(IF(AND($B12="",$C12="",$D12=""),IF(COUNTA($E12:$L12)>0,"⚠ Pick an exercise",""),IF($B12<>"",IF(COUNTA($C12:$K12)>0,"⚠ Put the section header on its own row","§ Section header"),IF(AND($C12<>"",$D12<>""),"⚠ Use Library OR Custom, not both",IF(AND($D12<>"",$E12=""),"⚠ Pick a muscle group for the custom exercise",IF(OR($H12="",$I12=""),"⚠ Enter Sets and Goal Reps",IF(IF($F12="",1=0,COUNTIF($F$7:$F$56,$F12)<2),"⚠ Superset "&$F12&" needs 2+ exercises",IF($C12<>"",IFERROR("✓ "&INDEX('Exercise Library'!$C$2:$C$319,MATCH($C12,'Exercise Library'!$B$2:$B$319,0))&IF(INDEX('Exercise Library'!$D$2:$D$319,MATCH($C12,'Exercise Library'!$B$2:$B$319,0))="Yes"," · demo video",""),"⚠ Not in the library — use Custom Exercise"),"✓ Custom ("&$E12&")"))))))),"⚠ Check this row")
A13: 7 | M13: =IFERROR(IF(AND($B13="",$C13="",$D13=""),IF(COUNTA($E13:$L13)>0,"⚠ Pick an exercise",""),IF($B13<>"",IF(COUNTA($C13:$K13)>0,"⚠ Put the section header on its own row","§ Section header"),IF(AND($C13<>"",$D13<>""),"⚠ Use Library OR Custom, not both",IF(AND($D13<>"",$E13=""),"⚠ Pick a muscle group for the custom exercise",IF(OR($H13="",$I13=""),"⚠ Enter Sets and Goal Reps",IF(IF($F13="",1=0,COUNTIF($F$7:$F$56,$F13)<2),"⚠ Superset "&$F13&" needs 2+ exercises",IF($C13<>"",IFERROR("✓ "&INDEX('Exercise Library'!$C$2:$C$319,MATCH($C13,'Exercise Library'!$B$2:$B$319,0))&IF(INDEX('Exercise Library'!$D$2:$D$319,MATCH($C13,'Exercise Library'!$B$2:$B$319,0))="Yes"," · demo video",""),"⚠ Not in the library — use Custom Exercise"),"✓ Custom ("&$E13&")"))))))),"⚠ Check this row")
A14: 8 | M14: =IFERROR(IF(AND($B14="",$C14="",$D14=""),IF(COUNTA($E14:$L14)>0,"⚠ Pick an exercise",""),IF($B14<>"",IF(COUNTA($C14:$K14)>0,"⚠ Put the section header on its own row","§ Section header"),IF(AND($C14<>"",$D14<>""),"⚠ Use Library OR Custom, not both",IF(AND($D14<>"",$E14=""),"⚠ Pick a muscle group for the custom exercise",IF(OR($H14="",$I14=""),"⚠ Enter Sets and Goal Reps",IF(IF($F14="",1=0,COUNTIF($F$7:$F$56,$F14)<2),"⚠ Superset "&$F14&" needs 2+ exercises",IF($C14<>"",IFERROR("✓ "&INDEX('Exercise Library'!$C$2:$C$319,MATCH($C14,'Exercise Library'!$B$2:$B$319,0))&IF(INDEX('Exercise Library'!$D$2:$D$319,MATCH($C14,'Exercise Library'!$B$2:$B$319,0))="Yes"," · demo video",""),"⚠ Not in the library — use Custom Exercise"),"✓ Custom ("&$E14&")"))))))),"⚠ Check this row")
A15: 9 | M15: =IFERROR(IF(AND($B15="",$C15="",$D15=""),IF(COUNTA($E15:$L15)>0,"⚠ Pick an exercise",""),IF($B15<>"",IF(COUNTA($C15:$K15)>0,"⚠ Put the section header on its own row","§ Section header"),IF(AND($C15<>"",$D15<>""),"⚠ Use Library OR Custom, not both",IF(AND($D15<>"",$E15=""),"⚠ Pick a muscle group for the custom exercise",IF(OR($H15="",$I15=""),"⚠ Enter Sets and Goal Reps",IF(IF($F15="",1=0,COUNTIF($F$7:$F$56,$F15)<2),"⚠ Superset "&$F15&" needs 2+ exercises",IF($C15<>"",IFERROR("✓ "&INDEX('Exercise Library'!$C$2:$C$319,MATCH($C15,'Exercise Library'!$B$2:$B$319,0))&IF(INDEX('Exercise Library'!$D$2:$D$319,MATCH($C15,'Exercise Library'!$B$2:$B$319,0))="Yes"," · demo video",""),"⚠ Not in the library — use Custom Exercise"),"✓ Custom ("&$E15&")"))))))),"⚠ Check this row")
A16: 10 | M16: =IFERROR(IF(AND($B16="",$C16="",$D16=""),IF(COUNTA($E16:$L16)>0,"⚠ Pick an exercise",""),IF($B16<>"",IF(COUNTA($C16:$K16)>0,"⚠ Put the section header on its own row","§ Section header"),IF(AND($C16<>"",$D16<>""),"⚠ Use Library OR Custom, not both",IF(AND($D16<>"",$E16=""),"⚠ Pick a muscle group for the custom exercise",IF(OR($H16="",$I16=""),"⚠ Enter Sets and Goal Reps",IF(IF($F16="",1=0,COUNTIF($F$7:$F$56,$F16)<2),"⚠ Superset "&$F16&" needs 2+ exercises",IF($C16<>"",IFERROR("✓ "&INDEX('Exercise Library'!$C$2:$C$319,MATCH($C16,'Exercise Library'!$B$2:$B$319,0))&IF(INDEX('Exercise Library'!$D$2:$D$319,MATCH($C16,'Exercise Library'!$B$2:$B$319,0))="Yes"," · demo video",""),"⚠ Not in the library — use Custom Exercise"),"✓ Custom ("&$E16&")"))))))),"⚠ Check this row")
